{
 "cells": [
  {
   "cell_type": "code",
   "id": "initial_id",
   "metadata": {
    "collapsed": true,
    "ExecuteTime": {
     "end_time": "2024-06-06T19:35:29.468651Z",
     "start_time": "2024-06-06T19:35:28.836172Z"
    }
   },
   "source": [
    "# Import packages\n",
    "import numpy as np\n",
    "import h5py\n",
    "import matplotlib.pyplot as plt\n",
    "from pathlib import Path"
   ],
   "outputs": [],
   "execution_count": 1
  },
  {
   "metadata": {
    "ExecuteTime": {
     "end_time": "2024-06-06T19:45:14.703019Z",
     "start_time": "2024-06-06T19:45:13.838843Z"
    }
   },
   "cell_type": "code",
   "source": [
    "# Assign filename: file\n",
    "file = Path('test_data/dmrg_results.hdf5')\n",
    "\n",
    "\n",
    "with h5py.File(file, \"r\") as f:\n",
    "    # Print all root level object names (aka keys) \n",
    "    # these can be group or dataset names \n",
    "    print(\"Keys: %s\" % f.keys())\n",
    "    a_group_key = list(f.keys())[-6]\n",
    "    print(type(f[a_group_key]))\n",
    "    ds_obj = f[a_group_key] \n",
    "    print(ds_obj[\"result_storage_dict\"][()])"
   ],
   "id": "bd2e23045cf44e2c",
   "outputs": [
    {
     "name": "stdout",
     "output_type": "stream",
     "text": [
      "Keys: <KeysViewHDF5 ['dmrg_loop_001', 'dmrg_loop_002', 'dmrg_loop_003', 'dmrg_loop_004', 'dmrg_loop_005', 'dmrg_loop_006', 'dmrg_loop_007', 'dmrg_loop_008', 'dmrg_loop_009', 'dmrg_loop_010', 'dmrg_loop_011', 'dmrg_loop_012', 'dmrg_loop_013', 'dmrg_loop_014', 'dmrg_loop_015', 'dmrg_loop_016', 'dmrg_loop_017', 'dmrg_loop_018', 'dmrg_loop_019', 'dmrg_loop_020', 'dmrg_loop_021', 'dmrg_loop_022', 'dmrg_loop_023', 'dmrg_loop_024', 'dmrg_loop_025', 'dmrg_loop_026', 'dmrg_loop_027', 'dmrg_loop_028', 'dmrg_loop_029', 'dmrg_loop_030', 'dmrg_loop_031', 'final_dmrg_results', 'final_extrapolated_results', 'first_preloop_calc', 'parent_folder_name', 'second_preloop_calc', 'timing_data']>\n",
      "<class 'h5py._hl.group.Group'>\n"
     ]
    },
    {
     "ename": "KeyError",
     "evalue": "\"Unable to open object (object 'result_storage_dict' doesn't exist)\"",
     "output_type": "error",
     "traceback": [
      "\u001B[0;31m---------------------------------------------------------------------------\u001B[0m",
      "\u001B[0;31mKeyError\u001B[0m                                  Traceback (most recent call last)",
      "Cell \u001B[0;32mIn[21], line 12\u001B[0m\n\u001B[1;32m     10\u001B[0m \u001B[38;5;28mprint\u001B[39m(\u001B[38;5;28mtype\u001B[39m(f[a_group_key]))\n\u001B[1;32m     11\u001B[0m ds_obj \u001B[38;5;241m=\u001B[39m f[a_group_key] \n\u001B[0;32m---> 12\u001B[0m \u001B[38;5;28mprint\u001B[39m(\u001B[43mds_obj\u001B[49m\u001B[43m[\u001B[49m\u001B[38;5;124;43m\"\u001B[39;49m\u001B[38;5;124;43mresult_storage_dict\u001B[39;49m\u001B[38;5;124;43m\"\u001B[39;49m\u001B[43m]\u001B[49m[()])\n",
      "File \u001B[0;32mh5py/_objects.pyx:54\u001B[0m, in \u001B[0;36mh5py._objects.with_phil.wrapper\u001B[0;34m()\u001B[0m\n",
      "File \u001B[0;32mh5py/_objects.pyx:55\u001B[0m, in \u001B[0;36mh5py._objects.with_phil.wrapper\u001B[0;34m()\u001B[0m\n",
      "File \u001B[0;32m~/planted_solutions/planted_solutions/venv/lib/python3.9/site-packages/h5py/_hl/group.py:357\u001B[0m, in \u001B[0;36mGroup.__getitem__\u001B[0;34m(self, name)\u001B[0m\n\u001B[1;32m    355\u001B[0m         \u001B[38;5;28;01mraise\u001B[39;00m \u001B[38;5;167;01mValueError\u001B[39;00m(\u001B[38;5;124m\"\u001B[39m\u001B[38;5;124mInvalid HDF5 object reference\u001B[39m\u001B[38;5;124m\"\u001B[39m)\n\u001B[1;32m    356\u001B[0m \u001B[38;5;28;01melif\u001B[39;00m \u001B[38;5;28misinstance\u001B[39m(name, (\u001B[38;5;28mbytes\u001B[39m, \u001B[38;5;28mstr\u001B[39m)):\n\u001B[0;32m--> 357\u001B[0m     oid \u001B[38;5;241m=\u001B[39m \u001B[43mh5o\u001B[49m\u001B[38;5;241;43m.\u001B[39;49m\u001B[43mopen\u001B[49m\u001B[43m(\u001B[49m\u001B[38;5;28;43mself\u001B[39;49m\u001B[38;5;241;43m.\u001B[39;49m\u001B[43mid\u001B[49m\u001B[43m,\u001B[49m\u001B[43m \u001B[49m\u001B[38;5;28;43mself\u001B[39;49m\u001B[38;5;241;43m.\u001B[39;49m\u001B[43m_e\u001B[49m\u001B[43m(\u001B[49m\u001B[43mname\u001B[49m\u001B[43m)\u001B[49m\u001B[43m,\u001B[49m\u001B[43m \u001B[49m\u001B[43mlapl\u001B[49m\u001B[38;5;241;43m=\u001B[39;49m\u001B[38;5;28;43mself\u001B[39;49m\u001B[38;5;241;43m.\u001B[39;49m\u001B[43m_lapl\u001B[49m\u001B[43m)\u001B[49m\n\u001B[1;32m    358\u001B[0m \u001B[38;5;28;01melse\u001B[39;00m:\n\u001B[1;32m    359\u001B[0m     \u001B[38;5;28;01mraise\u001B[39;00m \u001B[38;5;167;01mTypeError\u001B[39;00m(\u001B[38;5;124m\"\u001B[39m\u001B[38;5;124mAccessing a group is done with bytes or str, \u001B[39m\u001B[38;5;124m\"\u001B[39m\n\u001B[1;32m    360\u001B[0m                     \u001B[38;5;124m\"\u001B[39m\u001B[38;5;124mnot \u001B[39m\u001B[38;5;132;01m{}\u001B[39;00m\u001B[38;5;124m\"\u001B[39m\u001B[38;5;241m.\u001B[39mformat(\u001B[38;5;28mtype\u001B[39m(name)))\n",
      "File \u001B[0;32mh5py/_objects.pyx:54\u001B[0m, in \u001B[0;36mh5py._objects.with_phil.wrapper\u001B[0;34m()\u001B[0m\n",
      "File \u001B[0;32mh5py/_objects.pyx:55\u001B[0m, in \u001B[0;36mh5py._objects.with_phil.wrapper\u001B[0;34m()\u001B[0m\n",
      "File \u001B[0;32mh5py/h5o.pyx:189\u001B[0m, in \u001B[0;36mh5py.h5o.open\u001B[0;34m()\u001B[0m\n",
      "\u001B[0;31mKeyError\u001B[0m: \"Unable to open object (object 'result_storage_dict' doesn't exist)\""
     ]
    }
   ],
   "execution_count": 21
  },
  {
   "metadata": {
    "ExecuteTime": {
     "end_time": "2024-06-06T19:52:41.515476Z",
     "start_time": "2024-06-06T19:52:41.327313Z"
    }
   },
   "cell_type": "code",
   "source": [
    "file_path = Path(\"F.MPS.ket_optimized.32\")\n",
    "with open(file_path, 'r') as file:\n",
    "    lines = file.readlines()\n",
    "    print(lines)"
   ],
   "id": "e70dd17e7d219f14",
   "outputs": [
    {
     "ename": "UnicodeDecodeError",
     "evalue": "'utf-8' codec can't decode byte 0xf0 in position 80: invalid continuation byte",
     "output_type": "error",
     "traceback": [
      "\u001B[0;31m---------------------------------------------------------------------------\u001B[0m",
      "\u001B[0;31mUnicodeDecodeError\u001B[0m                        Traceback (most recent call last)",
      "Cell \u001B[0;32mIn[22], line 3\u001B[0m\n\u001B[1;32m      1\u001B[0m file_path \u001B[38;5;241m=\u001B[39m Path(\u001B[38;5;124m\"\u001B[39m\u001B[38;5;124mF.MPS.ket_optimized.32\u001B[39m\u001B[38;5;124m\"\u001B[39m)\n\u001B[1;32m      2\u001B[0m \u001B[38;5;28;01mwith\u001B[39;00m \u001B[38;5;28mopen\u001B[39m(file_path, \u001B[38;5;124m'\u001B[39m\u001B[38;5;124mr\u001B[39m\u001B[38;5;124m'\u001B[39m) \u001B[38;5;28;01mas\u001B[39;00m file:\n\u001B[0;32m----> 3\u001B[0m     lines \u001B[38;5;241m=\u001B[39m \u001B[43mfile\u001B[49m\u001B[38;5;241;43m.\u001B[39;49m\u001B[43mreadlines\u001B[49m\u001B[43m(\u001B[49m\u001B[43m)\u001B[49m\n\u001B[1;32m      4\u001B[0m     \u001B[38;5;28mprint\u001B[39m(lines)\n",
      "File \u001B[0;32m/Applications/Xcode.app/Contents/Developer/Library/Frameworks/Python3.framework/Versions/3.9/lib/python3.9/codecs.py:322\u001B[0m, in \u001B[0;36mBufferedIncrementalDecoder.decode\u001B[0;34m(self, input, final)\u001B[0m\n\u001B[1;32m    319\u001B[0m \u001B[38;5;28;01mdef\u001B[39;00m \u001B[38;5;21mdecode\u001B[39m(\u001B[38;5;28mself\u001B[39m, \u001B[38;5;28minput\u001B[39m, final\u001B[38;5;241m=\u001B[39m\u001B[38;5;28;01mFalse\u001B[39;00m):\n\u001B[1;32m    320\u001B[0m     \u001B[38;5;66;03m# decode input (taking the buffer into account)\u001B[39;00m\n\u001B[1;32m    321\u001B[0m     data \u001B[38;5;241m=\u001B[39m \u001B[38;5;28mself\u001B[39m\u001B[38;5;241m.\u001B[39mbuffer \u001B[38;5;241m+\u001B[39m \u001B[38;5;28minput\u001B[39m\n\u001B[0;32m--> 322\u001B[0m     (result, consumed) \u001B[38;5;241m=\u001B[39m \u001B[38;5;28;43mself\u001B[39;49m\u001B[38;5;241;43m.\u001B[39;49m\u001B[43m_buffer_decode\u001B[49m\u001B[43m(\u001B[49m\u001B[43mdata\u001B[49m\u001B[43m,\u001B[49m\u001B[43m \u001B[49m\u001B[38;5;28;43mself\u001B[39;49m\u001B[38;5;241;43m.\u001B[39;49m\u001B[43merrors\u001B[49m\u001B[43m,\u001B[49m\u001B[43m \u001B[49m\u001B[43mfinal\u001B[49m\u001B[43m)\u001B[49m\n\u001B[1;32m    323\u001B[0m     \u001B[38;5;66;03m# keep undecoded input until the next call\u001B[39;00m\n\u001B[1;32m    324\u001B[0m     \u001B[38;5;28mself\u001B[39m\u001B[38;5;241m.\u001B[39mbuffer \u001B[38;5;241m=\u001B[39m data[consumed:]\n",
      "\u001B[0;31mUnicodeDecodeError\u001B[0m: 'utf-8' codec can't decode byte 0xf0 in position 80: invalid continuation byte"
     ]
    }
   ],
   "execution_count": 22
  },
  {
   "metadata": {},
   "cell_type": "code",
   "outputs": [],
   "execution_count": null,
   "source": "",
   "id": "6d72104a2b5dc103"
  }
 ],
 "metadata": {
  "kernelspec": {
   "display_name": "Python 3",
   "language": "python",
   "name": "python3"
  },
  "language_info": {
   "codemirror_mode": {
    "name": "ipython",
    "version": 2
   },
   "file_extension": ".py",
   "mimetype": "text/x-python",
   "name": "python",
   "nbconvert_exporter": "python",
   "pygments_lexer": "ipython2",
   "version": "2.7.6"
  }
 },
 "nbformat": 4,
 "nbformat_minor": 5
}
